<?xml version="1.0" encoding="utf-8"?>
<robot name="icar" xmlns:xacro="http://ros.org/wiki/xacro">
	<include filename="$(find icar_description)/urdf/common_properties.xacro" />
	<include filename="$(find icar_description)/urdf/icar.gazebo.xacro" />
	<link name="base_footprint" />
	<!-- Body -->
	<property name="body_mass" value="0.2" />
	<property name="body_length" value="0.15" />
	<property name="body_width" value="0.15" />
	<property name="body_height" value="0.038" />
	<property name="body_height_offset" value="0.019" />
	<joint name="base_joint" type="fixed">
		<parent link="base_footprint" />
		<child link="base_link" />
		<origin xyz="0.053 0.0 0.0" rpy="0 0 0" />
	</joint>
	<link name="base_link">
		<box_inertial_matrix m="${body_mass}" l="${body_length}" w="${body_width}" h="${body_height}" zoffset="${body_height_offset}" />
		<visual>
			<origin xyz="0 0 0" rpy="0 0 0" />
			<geometry>
				<mesh filename="package://icar_description/meshes/body.stl" />
			</geometry>
			<material name="grey" />
		</visual>
		<collision>
			<origin xyz="0 0 ${body_height_offset}" rpy="0 0 0" />
			<geometry>
				<box size="${body_length} ${body_width} ${body_height}" />
			</geometry>
		</collision>
	</link>
	<!-- Wheel -->
	<property name="wheel_mass" value="0.02" />
	<property name="wheel_radius" value="0.045" />
	<property name="wheel_height" value="0.006" />
	<property name="wheel_y_offset" value="0.000" />
	<joint name="base_left_wheel_joint" type="continuous">
		<origin xyz="-0.0533 0.065 0.024" rpy="0 0 0" />
		<parent link="base_link" />
		<child link="left_wheel_link" />
		<axis xyz="0 1 0" />
	</joint>
	<link name="left_wheel_link">
		<cylinder_inertial_matrix m="${wheel_mass}" r="${wheel_radius}" h="${wheel_height}" yoffset="${wheel_y_offset}" />
		<visual>
			<origin xyz="0 0 0" rpy="0 0 0" />
			<geometry>
				<mesh filename="package://icar_description/meshes/wheel.stl" />
			</geometry>
			<material name="white" />
		</visual>
		<collision>
			<origin xyz="0 0 0" rpy="1.5708 0 0" />
			<geometry>
				<cylinder length="${wheel_height}" radius="${wheel_radius}" />
			</geometry>
		</collision>
	</link>
	<joint name="base_right_wheel_joint" type="continuous">
		<origin xyz="-0.0533 -0.065 0.024" rpy="0 0 3.1415926" />
		<parent link="base_link" />
		<child link="right_wheel_link" />
		<axis xyz="0 -1 0" />
	</joint>
	<link name="right_wheel_link">
		<cylinder_inertial_matrix m="${wheel_mass}" r="${wheel_radius}" h="${wheel_height}" yoffset="${wheel_y_offset}" />
		<visual>
			<origin xyz="0 0 0" rpy="0 0 0" />
			<geometry>
				<mesh filename="package://icar_description/meshes/wheel.stl" />
			</geometry>
			<material name="white" />
		</visual>
		<collision>
			<origin xyz="0 0 0" rpy="1.5708 0 0" />
			<geometry>
				<cylinder length="${wheel_height}" radius="${wheel_radius}" />
			</geometry>
		</collision>
	</link>
	<!-- Caster -->
	<property name="caster_radius" value="0.006" />
	<property name="caster_mass" value="0.005" />
	<joint name="baseToCaster_joint" type="fixed">
		<origin xyz="0.049373 0 -0.0126" rpy="0 0 0" />
		<parent link="base_link" />
		<child link="caster_link" />
		<axis xyz="0 0 0" />
	</joint>
	<link name="caster_link">
		<sphere_inertial_matrix m="${caster_mass}" r="${caster_radius}" />
		<visual>
			<origin xyz="0 0 0 " rpy="0 0 0" />
			<geometry>
				<sphere radius="${caster_radius}" />
			</geometry>
			<material name="Black" />
		</visual>
		<collision>
			<geometry>
				<sphere radius="${caster_radius}" />
			</geometry>
			<origin xyz="0 0 0 " rpy="0 0 0" />
		</collision>
	</link>
	<!-- Lidar -->
	<joint name="base_scan_joint" type="fixed">
		<parent link="base_link" />
		<child link="base_scan" />
		<origin xyz="-0.012 0 0.122" rpy="0 0 0" />
	</joint>
	<link name="base_scan">
		<visual>
			<origin xyz="0 0 0.0" rpy="0 0 0" />
			<geometry>
				<mesh filename="package://icar_description/meshes/lds.stl" scale="0.001 0.001 0.001" />
			</geometry>
			<material name="dark" />
		</visual>
		<collision>
			<origin xyz="0.015 0 -0.0065" rpy="0 0 0" />
			<geometry>
				<cylinder length="0.0315" radius="0.055" />
			</geometry>
		</collision>
		<inertial>
			<mass value="0.114" />
			<origin xyz="0 0 0" />
			<inertia ixx="0.001" ixy="0.0" ixz="0.0" iyy="0.001" iyz="0.0" izz="0.001" />
		</inertial>
	</link>
	<!-- Camera -->
	<joint name="camera_joint" type="fixed">
		<origin xyz="0.073 -0.011 0.084" rpy="0 0 0" />
		<parent link="base_link" />
		<child link="camera_link" />
	</joint>
	<link name="camera_link">
		<collision>
			<origin xyz="0.005 0.011 0.013" rpy="0 0 0" />
			<geometry>
				<box size="0.015 0.030 0.027" />
			</geometry>
		</collision>
	</link>
	<joint name="camera_rgb_joint" type="fixed">
		<origin xyz="0.003 0.011 0.009" rpy="0 0 0" />
		<parent link="camera_link" />
		<child link="camera_rgb_frame" />
	</joint>
	<link name="camera_rgb_frame" />
	<joint name="camera_rgb_optical_joint" type="fixed">
		<origin xyz="0 0 0" rpy="-1.57 0 -1.57" />
		<parent link="camera_rgb_frame" />
		<child link="camera_rgb_optical_frame" />
	</joint>
	<link name="camera_rgb_optical_frame" />
	<!-- Imu -->
	<joint name="imu_joint" type="fixed">
		<parent link="base_link" />
		<child link="imu_link" />
		<origin xyz="0 0 0.030" rpy="0 0 0" />
	</joint>
	<link name="imu_link" />
</robot>
