<?xml version="1.0" encoding="utf-8"?>
<robot name="icar"
    xmlns:xacro="http://ros.org/wiki/xacro">
    <xacro:include filename="$(find icar_description)/urdf/common_properties.xacro"/>
    <xacro:include filename="$(find icar_description)/urdf/icar.gazebo.xacro"/>

    <link name="base_footprint"/>

    <joint name="base_joint" type="fixed">
        <parent link="base_footprint"/>
        <child link="base_link"/>
        <origin xyz="0.053227 0.0 0.000" rpy="0 0 0"/>
    </joint>

    <link name="base_link">
        <inertial>
            <origin xyz="-0.012175 0 0.014958" rpy="0 0 0" />
            <mass value="0.2" />
            <inertia ixx="0.00028384" ixy="-4.2864E-15" ixz="-3.2265E-13" iyy="0.00035198" iyz="1.4426E-09" izz="0.00060387" />
        </inertial>

        <visual>
            <origin xyz="0 0 0" rpy="0 0 0" />
            <geometry>
                <mesh filename="package://icar_description/meshes/base_link.STL" />
            </geometry>
            <material name="">
                <color rgba="0.75294 0.75294 0.75294 1" />
            </material>
        </visual>

        <collision>
            <origin xyz="0 0 0.05" rpy="0 0 0" />
            <geometry>
                <box size="0.150 0.150 0.010"/>
            </geometry>
        </collision>
    </link>


    <joint name="baseToLeftWheel_joint" type="continuous">
        <origin xyz="-0.053227 0.065 0.024" rpy="-1.5708 0 0" />
        <parent link="base_link" />
        <child link="leftWheel_link" />
        <axis xyz="0 0 1" />
    </joint>

    <link name="leftWheel_link">
        <inertial>
            <origin xyz="-0.00014991 -1.6484E-05 0.0027771" rpy="0 0 0" />
            <mass value="0.01" />
            <inertia ixx="1.1321E-05" ixy="4.6749E-08" ixz="-5.5666E-14" iyy="1.1391E-05" iyz="-1.7219E-14" izz="2.2583E-05" />
        </inertial>

        <visual>
            <origin xyz="0 0 0" rpy="0 0 0" />
            <geometry>
                <mesh filename="package://icar_description/meshes/leftWheel_link.STL" />
            </geometry>
            <material name="">
                <color rgba="0.62745 0.62745 0.62745 1" />
            </material>
        </visual>

        <collision>
            <origin xyz="0 0 0" rpy="0 0 0" />
            <geometry>
                <cylinder length="0.006" radius="0.045"/>
            </geometry>
        </collision>
    </link>



    <joint name="baseToRightWheel_joint" type="continuous">
        <origin xyz="-0.053227 -0.065 0.024" rpy="-1.5708 0 3.1415926" />
        <parent link="base_link" />
        <child link="rightWheel_link" />
        <axis xyz="0 0 -1" />
    </joint>

    <link name="rightWheel_link">
        <inertial>
            <origin xyz="-0.00014991 -1.6484E-05 0.0032771" rpy="0 0 0" />
            <mass value="0.04" />
            <inertia ixx="1.1321E-05" ixy="4.6749E-08" ixz="-5.5666E-14" iyy="1.1391E-05" iyz="-1.7219E-14" izz="2.2583E-05" />
        </inertial>
        <visual>
            <origin xyz="0 0 0" rpy="0 0 0" />
            <geometry>
                <mesh filename="package://icar_description/meshes/rightWheel_link.STL" />
            </geometry>
            <material name="">
                <color rgba="0.96471 0.96471 0.95294 1" />
            </material>
        </visual>
        <collision>
            <origin xyz="0 0 0" rpy="0 0 0" />
            <geometry>
                <cylinder length="0.006" radius="0.045"/>
                <!-- <mesh filename="package://icar_description/meshes/rightWheel_link.STL" /> -->
            </geometry>
        </collision>
    </link>


    <joint name="baseToCaster_joint" type="fixed">
        <origin xyz="0.049373 0 -0.0126" rpy="0 0.0 0" />
        <parent link="base_link" />
        <child link="caster_link" />
        <axis xyz="0 0 0" />
    </joint>

    <!-- Caster radius and mass -->
    <xacro:property name="caster_radius" value="0.006" />
    <xacro:property name="caster_mass" value="0.005" />

    <link name="caster_link">
        <visual>
            <origin xyz="0 0 0 " rpy="0 0 0" />
            <geometry>
                <sphere radius="${caster_radius}" />
            </geometry>
            <material name="Black" />
        </visual>
        <collision>
            <geometry>
                <sphere radius="${caster_radius}" />
            </geometry>
            <origin xyz="0 0 0 " rpy="0 0 0" />
        </collision>
        <sphere_inertial_matrix m="${caster_mass}" r="${caster_radius}" />
    </link>


    <joint name="baseToScan_joint" type="fixed">
        <parent link="base_link"/>
        <child link="base_scan"/>
        <origin xyz="-0.032 0 0.132" rpy="0 0 0"/>
    </joint>

    <link name="base_scan">
        <visual>
            <origin xyz="0 0 0.0" rpy="0 0 0"/>
            <geometry>
                <mesh filename="package://icar_description/meshes/lds.stl" scale="0.001 0.001 0.001"/>
            </geometry>
            <material name="dark"/>
        </visual>

        <collision>
            <origin xyz="0.015 0 -0.0065" rpy="0 0 0"/>
            <geometry>
                <cylinder length="0.0315" radius="0.055"/>
            </geometry>
        </collision>

        <inertial>
            <mass value="0.114" />
            <origin xyz="0 0 0" />
            <inertia ixx="0.001" ixy="0.0" ixz="0.0" iyy="0.001" iyz="0.0" izz="0.001" />
        </inertial>
    </link>


    <joint name="imu_joint" type="fixed">
        <parent link="base_link"/>
        <child link="imu_link"/>
        <origin xyz="0 0 0.030" rpy="0 0 0"/>
    </joint>

    <link name="imu_link"/>

</robot>
